Traceback (most recent call last):
  File "/opt/hostedtoolcache/Python/3.9.7/x64/lib/python3.9/site-packages/jupyter_cache/executors/utils.py", line 51, in single_nb_execution
    executenb(
  File "/opt/hostedtoolcache/Python/3.9.7/x64/lib/python3.9/site-packages/nbclient/client.py", line 1117, in execute
    return NotebookClient(nb=nb, resources=resources, km=km, **kwargs).execute()
  File "/opt/hostedtoolcache/Python/3.9.7/x64/lib/python3.9/site-packages/nbclient/util.py", line 78, in wrapped
    return just_run(coro(*args, **kwargs))
  File "/opt/hostedtoolcache/Python/3.9.7/x64/lib/python3.9/site-packages/nbclient/util.py", line 57, in just_run
    return loop.run_until_complete(coro)
  File "/opt/hostedtoolcache/Python/3.9.7/x64/lib/python3.9/asyncio/base_events.py", line 642, in run_until_complete
    return future.result()
  File "/opt/hostedtoolcache/Python/3.9.7/x64/lib/python3.9/site-packages/nbclient/client.py", line 558, in async_execute
    await self.async_execute_cell(
  File "/opt/hostedtoolcache/Python/3.9.7/x64/lib/python3.9/site-packages/nbclient/client.py", line 862, in async_execute_cell
    self._check_raise_for_error(cell, exec_reply)
  File "/opt/hostedtoolcache/Python/3.9.7/x64/lib/python3.9/site-packages/nbclient/client.py", line 765, in _check_raise_for_error
    raise CellExecutionError.from_cell_and_msg(cell, exec_reply_content)
nbclient.exceptions.CellExecutionError: An error occurred while executing the following cell:
------------------
test_pi=np.zeros(10)
for i in range(0,10):
    test_pi[i]=montecarlopi(1000);

print('mean value for pi = %f'%np.mean(test_pi))
print('standard deviation is %f'%np.std(test_pi))
print('actual pi is %f'%np.pi)
------------------

[0;31m---------------------------------------------------------------------------[0m
[0;31mTypeError[0m                                 Traceback (most recent call last)
[0;32m/tmp/ipykernel_1879/1037623061.py[0m in [0;36m<module>[0;34m[0m
[1;32m      1[0m [0mtest_pi[0m[0;34m=[0m[0mnp[0m[0;34m.[0m[0mzeros[0m[0;34m([0m[0;36m10[0m[0;34m)[0m[0;34m[0m[0;34m[0m[0m
[1;32m      2[0m [0;32mfor[0m [0mi[0m [0;32min[0m [0mrange[0m[0;34m([0m[0;36m0[0m[0;34m,[0m[0;36m10[0m[0;34m)[0m[0;34m:[0m[0;34m[0m[0;34m[0m[0m
[0;32m----> 3[0;31m     [0mtest_pi[0m[0;34m[[0m[0mi[0m[0;34m][0m[0;34m=[0m[0mmontecarlopi[0m[0;34m([0m[0;36m1000[0m[0;34m)[0m[0;34m;[0m[0;34m[0m[0;34m[0m[0m
[0m[1;32m      4[0m [0;34m[0m[0m
[1;32m      5[0m [0mprint[0m[0;34m([0m[0;34m'mean value for pi = %f'[0m[0;34m%[0m[0mnp[0m[0;34m.[0m[0mmean[0m[0;34m([0m[0mtest_pi[0m[0;34m)[0m[0;34m)[0m[0;34m[0m[0;34m[0m[0m

[0;32m/tmp/ipykernel_1879/3128032761.py[0m in [0;36mmontecarlopi[0;34m(N)[0m
[1;32m     13[0m [0;34m[0m[0m
[1;32m     14[0m [0;34m[0m[0m
[0;32m---> 15[0;31m     [0mx[0m [0;34m=[0m [0mrng[0m[0;34m.[0m[0mrandom[0m[0;34m([0m[0mN[0m[0;34m,[0m[0;36m1[0m[0;34m)[0m[0;34m;[0m[0;34m[0m[0;34m[0m[0m
[0m[1;32m     16[0m     [0my[0m [0;34m=[0m [0mrng[0m[0;34m.[0m[0mrandom[0m[0;34m([0m[0mN[0m[0;34m,[0m[0;36m1[0m[0;34m)[0m[0;34m;[0m[0;34m[0m[0;34m[0m[0m
[1;32m     17[0m     [0mR[0m[0;34m=[0m[0mnp[0m[0;34m.[0m[0msqrt[0m[0;34m([0m[0mx[0m[0;34m**[0m[0;36m2[0m[0;34m+[0m[0my[0m[0;34m**[0m[0;36m2[0m[0;34m)[0m[0;34m;[0m [0;31m# compute radius[0m[0;34m[0m[0;34m[0m[0m

[0;32m_generator.pyx[0m in [0;36mnumpy.random._generator.Generator.random[0;34m()[0m

[0;31mTypeError[0m: Cannot interpret '1' as a data type
TypeError: Cannot interpret '1' as a data type

